Workbook
Name SegmentaçãodeDados_age_range: #N/A
Name SegmentaçãodeDados_customer_risk1: #N/A
Name SegmentaçãodeDados_gender1: #N/A
Name SegmentaçãodeDados_num_credit_cards: #N/A

Sheet cards_dataset
A1: id | B1: client_id | C1: card_brand | D1: card_type | E1: card_number | F1: expires | G1: cvv | H1: has_chip | I1: num_cards_issued | J1: credit_limit | K1: acct_open_date | L1: year_pin_last_changed | M1: card_on_dark_web
A2: 4524 | B2: 825 | C2: Visa | D2: Debit | E2: 4.3446765e+15 | F2: 44896 | G2: 623 | H2: YES | I2: 2 | J2: 24295 | K2: 37500 | L2: 2008 | M2: No
A3: 2731 | B3: 825 | C3: Visa | D3: Debit | E3: 4.956966e+15 | F3: 44166 | G3: 393 | H3: YES | I3: 2 | J3: 21968 | K3: 41730 | L3: 2014 | M3: No
A4: 3701 | B4: 825 | C4: Visa | D4: Debit | E4: 4.5823135e+15 | F4: 45323 | G4: 719 | H4: YES | I4: 2 | J4: 46414 | K4: 37803 | L4: 2004 | M4: No
A5: 42 | B5: 825 | C5: Visa | D5: Credit | E5: 4.8794941e+15 | F5: 45505 | G5: 693 | H5: NO | I5: 1 | J5: 12400 | K5: 37622 | L5: 2012 | M5: No
A6: 4659 | B6: 825 | C6: Mastercard | D6: Debit (Prepaid) | E6: 5.7228747e+15 | F6: 39873 | G6: 75 | H6: YES | I6: 1 | J6: 28 | K6: 39692 | L6: 2009 | M6: No
A7: 4537 | B7: 1746 | C7: Visa | D7: Credit | E7: 4.4048989e+15 | F7: 37865 | G7: 736 | H7: YES | I7: 1 | J7: 27500 | K7: 37865 | L7: 2012 | M7: No
A8: 1278 | B8: 1746 | C8: Visa | D8: Debit | E8: 4.001483e+15 | F8: 44743 | G8: 972 | H8: YES | I8: 2 | J8: 28508 | K8: 40575 | L8: 2011 | M8: No
A9: 3687 | B9: 1746 | C9: Mastercard | D9: Debit | E9: 5.6272207e+15 | F9: 44713 | G9: 48 | H9: YES | I9: 2 | J9: 9022 | K9: 37803 | L9: 2015 | M9: No
A10: 3465 | B10: 1746 | C10: Mastercard | D10: Debit (Prepaid) | E10: 5.7113822e+15 | F10: 44136 | G10: 722 | H10: YES | I10: 2 | J10: 54 | K10: 40330 | L10: 2015 | M10: No
A11: 3754 | B11: 1746 | C11: Mastercard | D11: Debit (Prepaid) | E11: 5.7661215e+15 | F11: 44958 | G11: 908 | H11: YES | I11: 1 | J11: 99 | K11: 38899 | L11: 2012 | M11: No
A12: 5144 | B12: 1718 | C12: Mastercard | D12: Debit | E12: 5.4951992e+15 | F12: 44621 | G12: 677 | H12: YES | I12: 2 | J12: 31599 | K12: 40087 | L12: 2009 | M12: No
A13: 2029 | B13: 1718 | C13: Mastercard | D13: Debit | E13: 5.8044996e+15 | F13: 45108 | G13: 258 | H13: NO | I13: 2 | J13: 27480 | K13: 37316 | L13: 2008 | M13: No
... A6147: 3199 | B6147: 1110 | C6147: Visa | D6147: Credit | E6147: 4.9940113e+15 | F6147: 44166 | G6147: 120 | H6147: YES | I6147: 1 | J6147: 14400 | K6147: 42856 | L6147: 2017 | M6147: No

Sheet users_dataset
A1: id | B1: current_age | C1: retirement_age | D1: birth_year | E1: birth_month | F1: gender | G1: address | H1: latitude | I1: longitude | J1: per_capita_income | K1: yearly_income | L1: total_debt | M1: credit_score | N1: num_credit_cards | O1: debt_income_ratio | P1: customer_risk | Q1: score_range | R1: age_range
A2: 825 | B2: 53 | C2: 66 | D2: 1966 | E2: 11 | F2: Female | G2: 462 Rose Lane | H2: 34.15 | I2: -117.76 | J2: 29278 | K2: 59696 | L2: 127613 | M2: 787 | N2: 5 | O2: =L2/K2 -> 2.1377144 | P2: =IF(OR(M2<600,O2>0.7),"High Risk", IF(AND(M2>=600,M2<=750),"Medium Risk", "Low Risk")) -> High Risk | Q2: =FLOOR(M2,50)&"-"&FLOOR(M2,50)+49 -> 750-799 | R2: =IF(Tabela2[[#This Row],[current_age]]>=100,"100+",FLOOR(Tabela2[[#This Row],[current_age]],10)&"-"&FLOOR(Tabela2[[#This Row],[current_age]],10)+9) -> 50-59
A3: 1746 | B3: 53 | C3: 68 | D3: 1966 | E3: 12 | F3: Female | G3: 3606 Federal Boulevard | H3: 40.76 | I3: -73.74 | J3: 37891 | K3: 77254 | L3: 191349 | M3: 701 | N3: 5 | O3: =L3/K3 -> 2.4768815 | P3: =IF(OR(M3<600,O3>0.7),"High Risk", IF(AND(M3>=600,M3<=750),"Medium Risk", "Low Risk")) -> High Risk | Q3: =FLOOR(M3,50)&"-"&FLOOR(M3,50)+49 -> 700-749 | R3: =IF(Tabela2[[#This Row],[current_age]]>=100,"100+",FLOOR(Tabela2[[#This Row],[current_age]],10)&"-"&FLOOR(Tabela2[[#This Row],[current_age]],10)+9) -> 50-59
A4: 1718 | B4: 81 | C4: 67 | D4: 1938 | E4: 11 | F4: Female | G4: 766 Third Drive | H4: 34.02 | I4: -117.89 | J4: 22681 | K4: 33483 | L4: 196 | M4: 698 | N4: 5 | O4: =L4/K4 -> 0.0058537168 | P4: =IF(OR(M4<600,O4>0.7),"High Risk", IF(AND(M4>=600,M4<=750),"Medium Risk", "Low Risk")) -> Medium Risk | Q4: =FLOOR(M4,50)&"-"&FLOOR(M4,50)+49 -> 650-699 | R4: =IF(Tabela2[[#This Row],[current_age]]>=100,"100+",FLOOR(Tabela2[[#This Row],[current_age]],10)&"-"&FLOOR(Tabela2[[#This Row],[current_age]],10)+9) -> 80-89
A5: 708 | B5: 63 | C5: 63 | D5: 1957 | E5: 1 | F5: Female | G5: 3 Madison Street | H5: 40.71 | I5: -73.99 | J5: 163145 | K5: 249925 | L5: 202328 | M5: 722 | N5: 4 | O5: =L5/K5 -> 0.80955487 | P5: =IF(OR(M5<600,O5>0.7),"High Risk", IF(AND(M5>=600,M5<=750),"Medium Risk", "Low Risk")) -> High Risk | Q5: =FLOOR(M5,50)&"-"&FLOOR(M5,50)+49 -> 700-749 | R5: =IF(Tabela2[[#This Row],[current_age]]>=100,"100+",FLOOR(Tabela2[[#This Row],[current_age]],10)&"-"&FLOOR(Tabela2[[#This Row],[current_age]],10)+9) -> 60-69
A6: 1164 | B6: 43 | C6: 70 | D6: 1976 | E6: 9 | F6: Male | G6: 9620 Valley Stream Drive | H6: 37.76 | I6: -122.44 | J6: 53797 | K6: 109687 | L6: 183855 | M6: 675 | N6: 1 | O6: =L6/K6 -> 1.6761786 | P6: =IF(OR(M6<600,O6>0.7),"High Risk", IF(AND(M6>=600,M6<=750),"Medium Risk", "Low Risk")) -> High Risk | Q6: =FLOOR(M6,50)&"-"&FLOOR(M6,50)+49 -> 650-699 | R6: =IF(Tabela2[[#This Row],[current_age]]>=100,"100+",FLOOR(Tabela2[[#This Row],[current_age]],10)&"-"&FLOOR(Tabela2[[#This Row],[current_age]],10)+9) -> 40-49
A7: 68 | B7: 42 | C7: 70 | D7: 1977 | E7: 10 | F7: Male | G7: 58 Birch Lane | H7: 41.55 | I7: -90.6 | J7: 20599 | K7: 41997 | L7: 0 | M7: 704 | N7: 3 | O7: =L7/K7 -> 0 | P7: =IF(OR(M7<600,O7>0.7),"High Risk", IF(AND(M7>=600,M7<=750),"Medium Risk", "Low Risk")) -> Medium Risk | Q7: =FLOOR(M7,50)&"-"&FLOOR(M7,50)+49 -> 700-749 | R7: =IF(Tabela2[[#This Row],[current_age]]>=100,"100+",FLOOR(Tabela2[[#This Row],[current_age]],10)&"-"&FLOOR(Tabela2[[#This Row],[current_age]],10)+9) -> 40-49
A8: 1075 | B8: 36 | C8: 67 | D8: 1983 | E8: 12 | F8: Female | G8: 5695 Fifth Street | H8: 38.22 | I8: -85.74 | J8: 25258 | K8: 51500 | L8: 102286 | M8: 672 | N8: 3 | O8: =L8/K8 -> 1.9861359 | P8: =IF(OR(M8<600,O8>0.7),"High Risk", IF(AND(M8>=600,M8<=750),"Medium Risk", "Low Risk")) -> High Risk | Q8: =FLOOR(M8,50)&"-"&FLOOR(M8,50)+49 -> 650-699 | R8: =IF(Tabela2[[#This Row],[current_age]]>=100,"100+",FLOOR(Tabela2[[#This Row],[current_age]],10)&"-"&FLOOR(Tabela2[[#This Row],[current_age]],10)+9) -> 30-39
A9: 1711 | B9: 26 | C9: 67 | D9: 1993 | E9: 12 | F9: Male | G9: 1941 Ninth Street | H9: 45.51 | I9: -122.64 | J9: 26790 | K9: 54623 | L9: 114711 | M9: 728 | N9: 1 | O9: =L9/K9 -> 2.1000494 | P9: =IF(OR(M9<600,O9>0.7),"High Risk", IF(AND(M9>=600,M9<=750),"Medium Risk", "Low Risk")) -> High Risk | Q9: =FLOOR(M9,50)&"-"&FLOOR(M9,50)+49 -> 700-749 | R9: =IF(Tabela2[[#This Row],[current_age]]>=100,"100+",FLOOR(Tabela2[[#This Row],[current_age]],10)&"-"&FLOOR(Tabela2[[#This Row],[current_age]],10)+9) -> 20-29
A10: 1116 | B10: 81 | C10: 66 | D10: 1938 | E10: 7 | F10: Female | G10: 11 Spruce Avenue | H10: 40.32 | I10: -75.32 | J10: 26273 | K10: 42509 | L10: 2895 | M10: 755 | N10: 5 | O10: =L10/K10 -> 0.068103225 | P10: =IF(OR(M10<600,O10>0.7),"High Risk", IF(AND(M10>=600,M10<=750),"Medium Risk", "Low Risk")) -> Low Risk | Q10: =FLOOR(M10,50)&"-"&FLOOR(M10,50)+49 -> 750-799 | R10: =IF(Tabela2[[#This Row],[current_age]]>=100,"100+",FLOOR(Tabela2[[#This Row],[current_age]],10)&"-"&FLOOR(Tabela2[[#This Row],[current_age]],10)+9) -> 80-89
A11: 1752 | B11: 34 | C11: 60 | D11: 1986 | E11: 1 | F11: Female | G11: 887 Grant Street | H11: 29.97 | I11: -92.12 | J11: 18730 | K11: 38190 | L11: 81262 | M11: 810 | N11: 1 | O11: =L11/K11 -> 2.1278345 | P11: =IF(OR(M11<600,O11>0.7),"High Risk", IF(AND(M11>=600,M11<=750),"Medium Risk", "Low Risk")) -> High Risk | Q11: =FLOOR(M11,50)&"-"&FLOOR(M11,50)+49 -> 800-849 | R11: =IF(Tabela2[[#This Row],[current_age]]>=100,"100+",FLOOR(Tabela2[[#This Row],[current_age]],10)&"-"&FLOOR(Tabela2[[#This Row],[current_age]],10)+9) -> 30-39
A12: 192 | B12: 27 | C12: 66 | D12: 1992 | E12: 6 | F12: Male | G12: 888 Fifth Lane | H12: 38.65 | I12: -121.25 | J12: 27548 | K12: 56164 | L12: 15224 | M12: 761 | N12: 2 | O12: =L12/K12 -> 0.27106331 | P12: =IF(OR(M12<600,O12>0.7),"High Risk", IF(AND(M12>=600,M12<=750),"Medium Risk", "Low Risk")) -> Low Risk | Q12: =FLOOR(M12,50)&"-"&FLOOR(M12,50)+49 -> 750-799 | R12: =IF(Tabela2[[#This Row],[current_age]]>=100,"100+",FLOOR(Tabela2[[#This Row],[current_age]],10)&"-"&FLOOR(Tabela2[[#This Row],[current_age]],10)+9) -> 20-29
A13: 640 | B13: 29 | C13: 63 | D13: 1990 | E13: 9 | F13: Female | G13: 8677 Littlewood Lane | H13: 40.42 | I13: -104.74 | J13: 22427 | K13: 45727 | L13: 94016 | M13: 629 | N13: 1 | O13: =L13/K13 -> 2.0560282 | P13: =IF(OR(M13<600,O13>0.7),"High Risk", IF(AND(M13>=600,M13<=750),"Medium Risk", "Low Risk")) -> High Risk | Q13: =FLOOR(M13,50)&"-"&FLOOR(M13,50)+49 -> 600-649 | R13: =IF(Tabela2[[#This Row],[current_age]]>=100,"100+",FLOOR(Tabela2[[#This Row],[current_age]],10)&"-"&FLOOR(Tabela2[[#This Row],[current_age]],10)+9) -> 20-29
... A2001: 1110 | B2001: 21 | C2001: 60 | D2001: 1998 | E2001: 11 | F2001: Female | G2001: 472 Ocean View Street | H2001: 42.86 | I2001: -71.48 | J2001: 32325 | K2001: 65909 | L2001: 181261 | M2001: 673 | N2001: 2 | O2001: =L2001/K2001 -> 2.7501707 | P2001: =IF(OR(M2001<600,O2001>0.7),"High Risk", IF(AND(M2001>=600,M2001<=750),"Medium Risk", "Low Risk")) -> High Risk | Q2001: =FLOOR(M2001,50)&"-"&FLOOR(M2001,50)+49 -> 650-699 | R2001: =IF(Tabela2[[#This Row],[current_age]]>=100,"100+",FLOOR(Tabela2[[#This Row],[current_age]],10)&"-"&FLOOR(Tabela2[[#This Row],[current_age]],10)+9) -> 20-29

Sheet pivot_table_cards
B5: Rótulos de Linha | C5: Soma de credit_limit
B6: Amex | C6: 4597400
B7: Discover | C7: 2260600
B8: Mastercard | C8: 47042657
B9: Visa | C9: 34279041
B10: Total Geral | C10: 88179698

Sheet pivot_table_users
B3: Rótulos de Linha | C3: Soma de total_debt | D3: Soma de credit_score | E3: Soma de yearly_income | G3: Soma de total_debt | H3: Soma de yearly_income
B4: 0 | G4: 127419388 | H4: 91431764
B5: Low Risk | C5: 36199 | D5: 763 | E5: 59613
B6: 1 | G6: Rótulos de Linha | H6: Contagem de id
B7: Medium Risk | C7: 14587 | D7: 704 | E7: 45360 | G7: 450-499 | H7: 7
B8: 2 | G8: 500-549 | H8: 38
B9: High Risk | C9: 80850 | D9: 673 | E9: 27447 | G9: 550-599 | H9: 87
B10: 3 | G10: 600-649 | H10: 202
B11: Medium Risk | C11: 18693 | D11: 681 | E11: 27943 | G11: 650-699 | H11: 492
B12: 4 | G12: 700-749 | H12: 640
B13: High Risk | C13: 115362 | D13: 716 | E13: 76431 | G13: 750-799 | H13: 368
B14: 5 | G14: 800-849 | H14: 132
B15: Medium Risk | C15: 14042 | D15: 711 | E15: 20614 | G15: 850-899 | H15: 34
B16: 6 | G16: Total Geral | H16: 2000
B17: High Risk | C17: 111042 | D17: 782 | E17: 55854
B18: 7
B19: Medium Risk | C19: 21379 | D19: 650 | E19: 32682
B20: 8
B21: High Risk | C21: 33413 | D21: 699 | E21: 38497
B22: 9
B23: High Risk | C23: 89801 | D23: 540 | E23: 40988
B24: 10
B25: High Risk | C25: 94134 | D25: 727 | E25: 58865
B26: 11
B27: Medium Risk | C27: 0 | D27: 714 | E27: 67643
B28: 12
B29: High Risk | C29: 58187 | D29: 748 | E29: 37785
B30: 13
B31: High Risk | C31: 65919 | D31: 588 | E31: 32378
B32: 14
B33: Medium Risk | C33: 21134 | D33: 652 | E33: 32232
B34: 15 | G34: Rótulos de Linha | H34: Contagem de id
B35: Low Risk | C35: 12950 | D35: 788 | E35: 29673 | G35: High Risk | H35: 1515
B36: 16 | G36: Low Risk | H36: 161
B37: High Risk | C37: 19101 | D37: 681 | E37: 22158 | G37: Medium Risk | H37: 324
B38: 17 | G38: Total Geral | H38: 2000
B39: High Risk | C39: 21103 | D39: 759 | E39: 21867
B40: 18
B41: High Risk | C41: 94513 | D41: 637 | E41: 64340
B42: 19
...

Sheet dashboard
B2: Banking & Credit Risk Dashboard
B7: ="Total Customers: "&TEXT(GETPIVOTDATA("[Measures].[Contagem de id 2]",pivot_table_users!$G$6),"#,##0") -> Total Customers: 2,000 | F7: ="Avg Credit Score: "&TEXT(AVERAGE(pivot_table_users!$D$4:$D$4003),"#,##0") -> Avg Credit Score: 710 | I7: ="Total Credit Limit: $ "&TEXT(GETPIVOTDATA("[Measures].[Soma de credit_limit]",pivot_table_cards!$B$5),"#,##0.00") -> Total Credit Limit: $ 88,179,698.00 | L7: ="Total Debt: $ "&TEXT(GETPIVOTDATA("[Measures].[Soma de total_debt 3]",pivot_table_users!$G$3),"#,##0.00") -> Total Debt: $ 127,419,388.00 | P7: ="Avg Yearly Income: $ "&TEXT(AVERAGE(pivot_table_users!$E$4:$E$4003),"#,##0.00") -> Avg Yearly Income: $ 45,715.88 | S7: =IFERROR("High Risk Customers: "&TEXT(COUNTIF(pivot_table_users!$B$4:$B$4003,"High Risk"),"#,##0")&" "& TEXT(COUNTIF(pivot_table_users!$B$4:$B$4003,"High Risk")/GETPIVOTDATA("[Measures].[Contagem de id 2]",pivot_table_users!$G$6),"##.#%")&" of total customers","No high risk customers") -> High Risk Customers: 1,515 75.8% of total customers
